Workbook

Sheet Leidos antes
A1: Titulo | B1: Autor | C1: Origen | D1: Fecha Inicio | E1: Fecha Fin | F1: Paginas | G1: Tipo | H1: Puntuación (del 1 al 10)
A2: Soldados de Salamina | B2: Javier Cercas | G2: Novela | H2: 6

Sheet Leidos 2008
A1: Titulo | B1: Autor | C1: Origen | D1: Fecha Inicio | E1: Fecha Fin | F1: Paginas | G1: Tipo | H1: Puntuación (del 1 al 10)
A2: La flecha del tiempo o La naturaleza de la ofensa | B2: Martin Amis | C2: N AMI fle | D2: 39813 | E2: 39813 | G2: Novela | H2: 8
A3: Jpod | B3: Douglas Coupland | C3: N COU jpo | D3: 39813 | E3: 39813 | G3: Novela | H3: 7
A4: Neuromante | B4: William Gibson | C4: N GIB neu | D4: 39813 | E4: 39813 | G4: Novela | H4: 5

Sheet Leidos 2009
A1: Titulo | B1: Autor | C1: Origen | D1: Fecha Inicio | E1: Fecha Fin | F1: Paginas | G1: Tipo | H1: Puntuación (del 1 al 10)
A2: El mono desnudo | B2: Desmond Morris | C2: 572 MOR mon | D2: 39824 | E2: 39827 | F2: 283 | G2: Ensayo | H2: 6
A3: Fahrenheit 451 | B3: Ray Bradbury | C3: N BRA far | D3: 39827 | E3: 39832 | F3: 183 | G3: Novela | H3: 6
A4: Las siete hijas de Eva | B4: Bryan Sykes | C4: 572 SYK sie | D4: 39832 | E4: 39841 | F4: 302 | G4: Ensayo | H4: 5
A5: Gomorra: un viaje al imperio económico y al sueño de poder de la Camorra | B5: Roberto Saviano | C5: Propio | D5: 39841 | E5: 39846 | F5: 324 | G5: Ensayo | H5: 8
A6: El viaje del elefante | B6: José Saramago | C6: Propio | D6: 39846 | E6: 39848 | F6: 270 | G6: Novela | H6: 9
A7: El porqué de las cosas | B7: Quim Monzó | C7: N MON por | D7: 39848 | E7: 39854 | F7: 138 | G7: Novela | H7: 6
A8: El sexto invierno | B8: Douglas Orgill y John Gribbin | C8: N ORG sex | D8: 39854 | E8: 39867 | F8: 412 | G8: Novela | H8: 5
A9: Kafka on the Shore | B9: Haruki Murakami | C9: N MUR kaf | D9: 39867 | E9: 39881 | F9: 584 | G9: Novela | H9: 6.5
A10: 2666 | B10: Roberto Bolaño | C10: Propio | D10: 39881 | E10: 39889 | F10: 1125 | G10: Novela | H10: 9.5
A11: Genoma: la autobiografía de una especie en 23 capítulos | B11: Matt Ridley | C11: 575 RID gen | D11: 39889 | E11: 39895 | F11: 388 | G11: Ensayo | H11: 6.5
A12: Trece campanadas | B12: Suso de Toro | C12: N TOR tre | D12: 39895 | E12: 39902 | F12: 397 | G12: Novela | H12: 4.5
A13: Piratas, corsarios, bucaneros y filibusteros | B13: Manuel Lucena Salmoral | C13: 910 LUC pir | D13: 39902 | E13: 39909 | F13: 313 | G13: Historia | H13: 5
A14: El antropólogo inocente: notas desde una choza de barro | B14: Nigel Barley | C14: 39 BAR ant | D14: 39909 | E14: 39918 | F14: 234 | G14: Ensayo | H14: 7
A15: La isla de los ciegos al color | B15: Oliver Sacks | C15: 617 SAC isl | D15: 39918 | E15: 39923 | F15: 312 | G15: Ensayo | H15: 6.5
A16: Indios carapálidas | B16: Ricardo Herren | C16: 97/98 HER ind | D16: 39923 | E16: 39930 | F16: 184 | G16: Ensayo | H16: 7
A17: Un trabajo muy sucio | B17: Christopher Moore | C17: Prestado | D17: 39930 | E17: 39935 | F17: 348 | G17: Novela | H17: 7.5
A18: En picado | B18: Nick Hornby | C18: N HOR enp | D18: 39935 | E18: 39939 | F18: 321 | G18: Novela | H18: 8
A19: La vida en las ventanas | B19: Andrés Neuman | C19: N NEU vid | D19: 39939 | E19: 39944 | F19: 199 | G19: Novela | H19: 6.5
A20: La piel fría | B20: Albert Sánchez Piñol | C20: N SAN pie | D20: 39944 | E20: 39956 | F20: 283 | G20: Novela | H20: 7.5
A21: El médico | B21: Noah Gordon | C21: Propio | D21: 39956 | E21: 39969 | F21: 873 | G21: Novela | H21: 6
A22: La isla de cemento | B22: J. G. Ballard | C22: N BAL isl | D22: 39969 | E22: 39974 | F22: 174 | G22: Novela | H22: 4
A23: Historias de Londres | B23: Enric González | C23: N GON his | D23: 39974 | E23: 39984 | F23: 185 | G23: Novela | H23: 6
A24: La chica que soñaba con una cerilla y un bidón de gasolina | B24: Stieg Larsson | C24: Prestado | D24: 39984 | E24: 39989 | F24: 752 | G24: Novela | H24: 8
A25: Polvo eres: peripecias y extravagancias de algunos cadáveres inquietos | B25: Nieves Concostrina | C25: B CON pol | D25: 39989 | E25: 39994 | F25: 394 | G25: Historia | H25: 6
A26: Jennifer Gobierno | B26: Max Barry | C26: N BAR jen | D26: 39994 | E26: 40001 | F26: 323 | G26: Novela | H26: 5
A27: Patas arriba | B27: Eduardo Galeano | C27: N GAL pat | D27: 40001 | E27: 40008 | F27: 365 | G27: Novela | H27: 7
A28: El corazón de las tinieblas | B28: Joseph Conrad | C28: Prestado | D28: 40008 | E28: 40013 | F28: 139 | G28: Novela | H28: 5
A29: La maravillosa vida breve de Óscar Wao | B29: Junot Díaz | C29: Prestado | D29: 40013 | E29: 40021 | F29: 309 | G29: Novela | H29: 8
A30: Testigo de raza: un negro en la Alemania nazi | B30: Hans j. Massaquoi | C30: Propio | D30: 40021 | E30: 40022 | F30: 540 | G30: Biografía | H30: 3
A31: El Rey Rata | B31: China Miéville | C31: N MIE rey | D31: 40022 | E31: - | F31: 311 | G31: Novela | H31: -
A32: La batalla de Creta | B32: Antony Beevor | C32: 94 BEE bat | D32: 40029 | E32: 40035 | F32: 414 | G32: Historia | H32: 7
A33: El conde-duque de Olivares | B33: J.H. Elliott | C33: Propio | D33: 40035 | E33: 40061 | F33: 924 | G33: Historia | H33: 8.5
A34: Londres: una biografía | B34: Peter Ackroyd | C34: 941 ACK lon | D34: 40052 | E34: - | F34: 1007 | G34: Ensayo | H34: 6
A35: Patria | B35: Robert Harris | C35: N HAR pat | D35: 40062 | E35: 40065 | F35: 406 | G35: Novela | H35: 6
A36: La aventura de las lenguas en Occidente | B36: Henriette Walter | C36: 81(09) WAL ave | D36: 40066 | E36: 40077 | F36: 531 | G36: Ensayo | H36: 4.5
A37: La tercera ola | B37: Alvin Toffler | C37: 008 TOF ter | D37: 40079 | E37: - | F37: 494 | G37: Ensayo | H37: 3 | I37: Interesante pero obsoleto
A38: Los santos inocentes | B38: Miguel Delibes | C38: N DEL san | D38: 40085 | E38: 40085 | F38: 175 | G38: Novela | H38: 8
A39: American Psycho | B39: Bret Easton Ellis | C39: N ELL ame | D39: 40086 | E39: 40102 | F39: 477 | G39: Novela | H39: 7.5
A40: La reina en el palacio de las corrientes de aire | B40: Stieg Larsson | C40: Propio | D40: 40102 | E40: 40108 | F40: 812 | G40: Novela | H40: 8.5
...

Sheet Leidos 2010
A1: Titulo | B1: Autor | C1: Origen | D1: Fecha Inicio | E1: Fecha Fin | F1: Paginas | G1: Tipo | H1: Puntuación (del 1 al 10) | J1: Paginas efectivas leídas | K1: Libro Leido? | L1: Autor leido?
A2: El Proceso | B2: Franz Kafka | C2: Prestado | D2: 40135 | E2: 40442 | F2: 280 | G2: Novela | H2: 7 | J2: =IF(ISBLANK(E2),0,F2) -> 280 | K2: =IF(ISBLANK(E2),0,1) -> 1 | L2: =IF(ISBLANK(E2)," ",B2) -> Franz Kafka
A3: Simon´s cat | B3: Simon Tofield | C3: Propio | D3: 40184 | E3: 40184 | F3: 240 | G3: Comic | H3: 8 | J3: =IF(ISBLANK(E3),0,F3) -> 240 | K3: =IF(ISBLANK(E3),0,1) -> 1 | L3: =IF(ISBLANK(E3)," ",B3) -> Simon Tofield
A4: Diario : una novela | B4: Chuck Palahniuk | C4: N PAL dia | D4: 40186 | E4: 40192 | F4: 275 | G4: Novela | H4: 7.5 | J4: =IF(ISBLANK(E4),0,F4) -> 275 | K4: =IF(ISBLANK(E4),0,1) -> 1 | L4: =IF(ISBLANK(E4)," ",B4) -> Chuck Palahniuk
A5: Hitler, la novela gráfica | B5: Shigeru Mizuki | C5: Propio | D5: 40188 | E5: 40206 | F5: 208 | G5: Comic | H5: 9 | J5: =IF(ISBLANK(E5),0,F5) -> 208 | K5: =IF(ISBLANK(E5),0,1) -> 1 | L5: =IF(ISBLANK(E5)," ",B5) -> Shigeru Mizuki
A6: El año de la muerte de Ricardo Reis | B6: José Saramago | C6: N SAR año | D6: 40193 | E6: 40204 | F6: 527 | G6: Novela | H6: 7 | J6: =IF(ISBLANK(E6),0,F6) -> 527 | K6: =IF(ISBLANK(E6),0,1) -> 1 | L6: =IF(ISBLANK(E6)," ",B6) -> José Saramago
A7: Pregúntale al polvo | B7: John Fante | C7: N FAN pre | D7: 40205 | E7: 40210 | F7: 205 | G7: Novela | H7: 6 | J7: =IF(ISBLANK(E7),0,F7) -> 205 | K7: =IF(ISBLANK(E7),0,1) -> 1 | L7: =IF(ISBLANK(E7)," ",B7) -> John Fante
A8: Crimen y castigo | B8: Fedor Dostoyevski | C8: N DOS cri | D8: 40211 | E8: 40225 | F8: 703 | G8: Novela | H8: 8.5 | J8: =IF(ISBLANK(E8),0,F8) -> 703 | K8: =IF(ISBLANK(E8),0,1) -> 1 | L8: =IF(ISBLANK(E8)," ",B8) -> Fedor Dostoyevski
A9: Guía del Autoestopista Galáctico | B9: Douglas Adams | C9: ebook | D9: 40222 | E9: 40227 | F9: 174 | G9: Novela | H9: 8 | J9: =IF(ISBLANK(E9),0,F9) -> 174 | K9: =IF(ISBLANK(E9),0,1) -> 1 | L9: =IF(ISBLANK(E9)," ",B9) -> Douglas Adams
A10: La carretera | B10: Cormac McCarthy | C10: ebook | D10: 40228 | E10: 40233 | F10: 210 | G10: Novela | H10: 8 | J10: =IF(ISBLANK(E10),0,F10) -> 210 | K10: =IF(ISBLANK(E10),0,1) -> 1 | L10: =IF(ISBLANK(E10)," ",B10) -> Cormac McCarthy
A11: Q | B11: Luther Blissett | C11: ebook | D11: 40233 | E11: 40248 | F11: 641 | G11: Novela | H11: 7.5 | J11: =IF(ISBLANK(E11),0,F11) -> 641 | K11: =IF(ISBLANK(E11),0,1) -> 1 | L11: =IF(ISBLANK(E11)," ",B11) -> Luther Blissett
A12: La aventura de los godos | B12: Juan Antonio Cebrián | C12: ebook | D12: 40236 | E12: 40249 | F12: 232 | G12: Ensayo | H12: 7 | J12: =IF(ISBLANK(E12),0,F12) -> 232 | K12: =IF(ISBLANK(E12),0,1) -> 1 | L12: =IF(ISBLANK(E12)," ",B12) -> Juan Antonio Cebrián
A13: La mula | B13: Juan Eslava Galán | C13: ebook | D13: 40249 | E13: 40252 | F13: 272 | G13: Novela | H13: 7 | J13: =IF(ISBLANK(E13),0,F13) -> 272 | K13: =IF(ISBLANK(E13),0,1) -> 1 | L13: =IF(ISBLANK(E13)," ",B13) -> Juan Eslava Galán
... A57: En el camino | B57: Jack Kerouac | C57: ebook | D57: 40515 | E57: 40533 | F57: 368 | G57: Novela | H57: 8 | J57: =IF(ISBLANK(E57),0,F57) -> 368 | K57: =IF(ISBLANK(E57),0,1) -> 1 | L57: =IF(ISBLANK(E57)," ",B57) -> Jack Kerouac
F58: =SUM(F2:F57) -> 20051 | H58: =AVERAGE(H2:H57) -> 7.0625
A59: Estadísticas
A60: Nº Páginas Leídas | B60: Libros Leídos | C60: Media páginas por libro | D60: Autor más leido | E60: Tipo más leido
A61: =SUM(J2:J57) -> 20051 | B61: =SUM(K2:K57) -> 56 | C61: =ROUND(A61/B61,0) -> 358 | D61: {=INDEX(L2:L57,MAX(IF(COUNTIF($L$2:$L$57,L2:L57)=LARGE(COUNTIF($L$2:$L$57,L2:L57),1),ROW(L2:L57)*0))*0.1)} -> Franz Kafka

Sheet Leidos 2011
A1: Titulo | B1: Autor | C1: Origen | D1: Fecha Inicio | E1: Fecha Fin | F1: Paginas | G1: Tipo | H1: Puntuación (del 1 al 10) | I1: Num leidos | J1: Autor
A2: Política de hechos consumados | B2: Nacho Vegas | C2: Propio | D2: 40151 | E2: 40616 | F2: 94 | G2: Relatos | H2: 6 | I2: =NA() -> #N/A | J2: =B2 -> Nacho Vegas
A3: Revista Orsai | B3: Varios | C3: Revista | D3: 40553 | E3: 40612 | F3: 180 | G3: Revista | H3: 8 | I3: =NA() -> #N/A | J3: =B3 -> Varios
A4: El Misterio De Los Hititas | B4: C. W Ceram | C4: ebook | D4: 40513 | E4: 40550 | F4: 283 | G4: Historia | H4: 6 | I4: =NA() -> #N/A | J4: =B4 -> C. W Ceram
A5: Ciclo Barroco: Azogue | B5: Neal Stephenson | C5: ebook | D5: 40550 | E5: 40563 | F5: 400 | G5: Novela | H5: 8 | I5: =NA() -> #N/A | J5: =B5 -> Neal Stephenson
A6: Los Simpson y la filosofía | B6: Varios | C6: Propio | D6: 40562 | E6: 40590 | F6: 415 | G6: Ensayo | H6: 7.5 | I6: =NA() -> #N/A | J6: =B6 -> Varios
A7: Ciclo Barroco: El rey de los vagabundos | B7: Neal Stephenson | C7: ebook | D7: 40563 | E7: 40573 | F7: 320 | G7: Novela | H7: 8 | I7: =NA() -> #N/A | J7: =B7 -> Neal Stephenson
A8: La historia del mundo en seis tragos | B8: Tom Standage | C8: ebook | D8: 40573 | E8: 40578 | F8: 288 | G8: Ensayo | H8: 7 | I8: =NA() -> #N/A | J8: =B8 -> Tom Standage
A9: Guía Total Berlín | B9: Varios | C9: Propio | D9: 40577 | E9: 40633 | F9: 300 | G9: Guía | H9: 5 | I9: =NA() -> #N/A | J9: =B9 -> Varios
A10: La peste negra | B10: Luis Miguel Guerra | C10: Propio | D10: 40594 | E10: 40596 | F10: 318 | G10: Novela | H10: 6 | I10: =NA() -> #N/A | J10: =B10 -> Luis Miguel Guerra
A11: Ciclo Barroco: Odalisca | B11: Neal Stephenson | C11: ebook | D11: 40597 | E11: 40610 | F11: 360 | G11: Novela | H11: 7.5 | I11: =NA() -> #N/A | J11: =B11 -> Neal Stephenson
A12: Un general confederado de Big Sur | B12: Richard Brautigan | C12: Propio | D12: 40611 | E12: 40616 | F12: 167 | G12: Novela | H12: 6 | I12: =NA() -> #N/A | J12: =B12 -> Richard Brautigan
A13: Diarios de Bicicleta | B13: David Byrne | C13: Propio | D13: 40617 | E13: 40637 | F13: 362 | G13: Diario | H13: 7.5 | I13: =NA() -> #N/A | J13: =B13 -> David Byrne
... A49: Historia del tiempo | B49: Stephen Hawking | C49: ebook | D49: 40903 | E49: 40907 | F49: 248 | G49: Ensayo | H49: 6.5 | I49: =NA() -> #N/A | J49: =B49 -> Stephen Hawking
F50: =SUM(F2:F49) -> 18918 | H50: =AVERAGE(H2:H49) -> 6.98125
A51: Estadísticas
A52: Libros Leídos | B52: Media páginas por libro | C52: Autor más leido | D52: Tipo más leido
A53: =COUNTIF(E2:E49,">0") -> 48 | B53: =ROUND(F50/A53,0) -> 394 | C53: =INDEX(J2:J49,MATCH(MAX(I2:I49),I2:I49,0),1) -> #N/A

Sheet Leidos 2012
A1: Titulo | B1: Autor | C1: Origen | D1: Fecha Inicio | E1: Fecha Fin | F1: Paginas | G1: Tipo | H1: Puntuación (del 1 al 10) | I1: Num leidos | J1: Autor
A2: Revista Orsai IV | B2: Varios | C2: Revista | D2: 40750 | E2: 41002 | F2: 206 | G2: Revista | H2: 5 | I2: =NA() -> #N/A | J2: =B2 -> Varios
A3: 54 | B3: Wu-ming | C3: ebook | D3: 40910 | E3: 40924 | F3: 600 | G3: Novela | H3: 7 | I3: =NA() -> #N/A | J3: =B3 -> Wu-ming
A4: Porno | B4: Irvine Welsh | C4: ebook | D4: 40925 | E4: 40940 | F4: 320 | G4: Novela | H4: 8 | I4: =NA() -> #N/A | J4: =B4 -> Irvine Welsh
A5: En casa | B5: Bill Bryson | C5: Propio | D5: 40930 | E5: 40947 | F5: 672 | G5: Divulgación | H5: 8 | I5: =NA() -> #N/A | J5: =B5 -> Bill Bryson
A6: La Habana para un infante difunto | B6: Guillermo Cabrera Infante | C6: Propio | D6: 40941 | E6: 40965 | F6: 512 | G6: Novela | H6: 7 | I6: =NA() -> #N/A | J6: =B6 -> Guillermo Cabrera Infante
A7: Mata a tus idolos | B7: Luc Sante | C7: Propio | D7: 40951 | E7: 41063 | F7: 397 | G7: Relatos | H7: 6 | I7: =NA() -> #N/A | J7: =B7 -> Luc Sante
A8: Cerdeña | B8: Varios | C8: Propio | D8: 40959 | E8: 41060 | F8: 295 | G8: Guía | H8: 5 | J8: =B8 -> Varios
A9: Superviviente | B9: Chuck Palaniuk | C9: ebook | D9: 40966 | E9: 40969 | F9: 272 | G9: Novela | H9: 8 | I9: =NA() -> #N/A | J9: =B9 -> Chuck Palaniuk
A10: Revista Panenka #5 | B10: Varios | C10: Propio | D10: 40966 | E10: 40978 | F10: 114 | G10: Revista | H10: 7.5 | I10: =NA() -> #N/A | J10: =B10 -> Varios
A11: Los niños del Brasil | B11: Ira Levin | C11: ebook | D11: 40970 | E11: 40975 | F11: 304 | G11: Novela | H11: 6.5 | I11: =NA() -> #N/A | J11: =B11 -> Ira Levin
A12: La estrategia del perro loco | B12: Iñigo Sáenz de Ugarte | C12: ebook | D12: 40975 | E12: 40975 | F12: 50 | G12: Ensayo | H12: 8 | I12: =NA() -> #N/A | J12: =B12 -> Iñigo Sáenz de Ugarte
A13: Anatema | B13: Neal Stephenson | C13: ebook | D13: 40976 | E13: 40991 | F13: 736 | G13: Novela | H13: 8 | I13: =NA() -> #N/A | J13: =B13 -> Neal Stephenson
A14: Fargo Rock City | B14: Chuck Klosterman | C14: Propio | D14: 40986 | E14: 41015 | F14: 352 | G14: Ensayo | H14: 7 | I14: =NA() -> #N/A | J14: =B14 -> Chuck Klosterman
A15: Los Creadores | B15: Daniel J. Boorstin | C15: ebook | D15: 40993 | E15: 41025 | F15: 744 | G15: Ensayo | H15: 8 | I15: =NA() -> #N/A | J15: =B15 -> Daniel J. Boorstin
A16: Dinero | B16: Aristófanes | C16: ebook | D16: 41000 | E16: 41000 | F16: 77 | G16: Teatro | H16: 6 | I16: =NA() -> #N/A | J16: =B16 -> Aristófanes
A17: Todos los hombres del Führer | B17: Ferran Gallego | C17: Propio | D17: 41016 | E17: 41167 | F17: 576 | G17: Historia | H17: 7 | I17: =NA() -> #N/A | J17: =B17 -> Ferran Gallego
A18: La odisea | B18: Homero | C18: ebook | D18: 41025 | E18: 41042 | F18: 501 | G18: Epopeya | H18: 7 | I18: =NA() -> #N/A | J18: =B18 -> Homero
A19: Tierra de sal y arroz | B19: Kim Stanley Robinson | C19: ebook | D19: 41043 | E19: 41052 | F19: 718 | G19: Novela | H19: 5 | I19: =NA() -> #N/A | J19: =B19 -> Kim Stanley Robinson
A20: Del concilio al black power | B20: JdJ | C20: ebook | D20: 41052 | E20: 41052 | F20: 100 | G20: Historia | H20: 8 | I20: =NA() -> #N/A | J20: =B20 -> JdJ
... A41: American Gods | B41: Neil Gaiman | C41: ebook | D41: 41156 | E41: 41163 | F41: 477 | G41: Novela | H41: 8 | I41: =NA() -> #N/A | J41: =B41 -> Neil Gaiman
A42: La primera y la última humanidad | B42: Olaf Stapledon | C42: ebook | D42: 41163 | F42: 304 | G42: Novela | I42: =NA() -> #N/A | J42: =B42 -> Olaf Stapledon
A43: Un gran chico | B43: Nick Hornby | C43: ebook | D43: 41167 | E43: 41175 | F43: 360 | G43: Novela | H43: 7.5 | I43: =NA() -> #N/A | J43: =B43 -> Nick Hornby
A44: Amuleto | B44: Roberto Bolaño | C44: Propio | D44: 41168 | E44: 41216 | F44: 160 | G44: Novela | H44: 7.5 | I44: =NA() -> #N/A | J44: =B44 -> Roberto Bolaño
A45: La caída de Hyperion | B45: Dan Simmons | C45: ebook | D45: 41176 | E45: 41186 | F45: 736 | G45: Novela | H45: 7 | I45: =NA() -> #N/A | J45: =B45 -> Dan Simmons
A46: Col recalentada | B46: Irvine Welsh | C46: ebook | D46: 41187 | E46: 41199 | F46: 288 | G46: Relatos | H46: 7.5 | I46: =NA() -> #N/A | J46: =B46 -> Irvine Welsh
A47: El jardín colgante | B47: Javier Calvo | C47: ebook | D47: 41200 | E47: 41203 | F47: 368 | G47: Novela | H47: 8 | I47: =NA() -> #N/A | J47: =B47 -> Javier Calvo
A48: Verdes Valles, Colinas Rojas: La tierra convulsa | B48: Ramiro Pinilla | C48: ebook | D48: 41203 | E48: 41220 | F48: 744 | G48: Novela | H48: 8 | I48: =NA() -> #N/A | J48: =B48 -> Ramiro Pinilla
A49: Revista Libero #2 | B49: Varios | C49: Propio | D49: 41221 | E49: 41225 | F49: 130 | G49: Revista | H49: 6 | I49: =NA() -> #N/A | J49: =B49 -> Varios
A50: Sobre Camarón | B50: Carlos Lencero | C50: ebook | D50: 41220 | E50: 41227 | F50: 256 | G50: Musica | H50: 6.5 | I50: =NA() -> #N/A | J50: =B50 -> Carlos Lencero
A51: Monstruos invisibles | B51: Chuck Palahniuk | C51: ebook | D51: 41231 | E51: 41239 | F51: 272 | G51: Novela | H51: 5 | I51: =NA() -> #N/A | J51: =B51 -> Chuck Palahniuk
A52: Planeta Gigante | B52: Jack Vance | C52: ebook | D52: 41240 | E52: 41247 | F52: 250 | G52: Novela | H52: 6 | I52: =NA() -> #N/A | J52: =B52 -> Jack Vance
A53: Corona de flores | B53: Javier Calvo | C53: ebook | D53: 41248 | E53: 41258 | F53: 320 | G53: Novela | H53: 7.6 | I53: =NA() -> #N/A | J53: =B53 -> Javier Calvo
A54: Little brother | B54: Cory Doctorow | C54: ebook | D54: 41258 | E54: 41264 | F54: 384 | G54: Novela | H54: 7 | I54: =NA() -> #N/A | J54: =B54 -> Cory Doctorow
F55: =SUM(F2:F54) -> 19868 | H55: =AVERAGE(H2:H54) -> 6.9
A56: Estadísticas
A57: Libros Leídos | B57: Media páginas por libro | C57: Autor más leido | D57: Tipo más leido
A58: =COUNTIF(E2:E54,">0") -> 52 | B58: =ROUND(F55/A58,0) -> 382 | C58: =INDEX(J2:J54,MATCH(MAX(I2:I54),I2:I54,0),1) -> #N/A

Sheet Leídos 2013
A1: Titulo | B1: Autor | C1: Origen | D1: Fecha Inicio | E1: Fecha Fin | F1: Paginas | G1: Tipo | H1: Puntuación (del 1 al 10) | I1: Num leidos | J1: Autor
A2: Pedro Páramo;El llano en llamas | B2: Juan Rulfo | C2: Prestado | D2: 40150 | F2: 222 | G2: Novela | H2: - | I2: =NA() -> #N/A | J2: =B2 -> Juan Rulfo
A3: Ulises | B3: James Joyce | C3: Propio | D3: 40261 | F3: 910 | G3: Novela | H3: - | I3: =NA() -> #N/A | J3: =B3 -> James Joyce
A4: Diccionario del Diablo | B4: Ambrose Bierce | C4: ebook | D4: 40282 | F4: 480 | G4: Novela | H4: - | I4: =NA() -> #N/A | J4: =B4 -> Ambrose Bierce
A5: Johnny got his gun | B5: Dalton Trumbo | C5: ebook | D5: 40296 | F5: 209 | G5: Novela | H5: - | I5: =NA() -> #N/A | J5: =B5 -> Dalton Trumbo
A6: Nuestras hermanas las ratas | B6: Michel Dansel | C6: ebook | D6: 40366 | F6: 160 | G6: Ensayo | H6: - | I6: =NA() -> #N/A | J6: =B6 -> Michel Dansel
A7: Bolaño salvaje | B7: Varios | C7: Propio | D7: 40373 | F7: 502 | G7: Ensayo | H7: - | I7: =NA() -> #N/A | J7: =B7 -> Varios
A8: Historia de la Inquisición | B8: Primitivo Martínez | C8: ebook | D8: 40385 | F8: 384 | G8: Historia | H8: - | I8: =NA() -> #N/A | J8: =B8 -> Primitivo Martínez
A9: Nuestros orígenes | B9: Richard Leakey | C9: ebook | D9: 40438 | F9: 300 | G9: Antropología | H9: - | I9: =NA() -> #N/A | J9: =B9 -> Richard Leakey
A10: El libro de las ilusiones | B10: Paul Auster | C10: Propio | F10: 338 | G10: Novela | H10: - | I10: =NA() -> #N/A | J10: =B10 -> Paul Auster
A11: La búsqueda de la lengua perfecta | B11: Umberto Eco | C11: ebook | D11: 40655 | F11: 300 | G11: Ensayo | H11: - | I11: =NA() -> #N/A | J11: =B11 -> Umberto Eco
A12: La insurrección que viene | B12: Comité invisible | C12: Propio | D12: 40736 | F12: 144 | G12: Ensayo | H12: - | I12: =NA() -> #N/A | J12: =B12 -> Comité invisible
A13: Revista JotDown #1 | B13: Varios | C13: Propio | D13: 41084 | E13: 41365 | F13: 319 | G13: Revista | H13: 8 | I13: =NA() -> #N/A | J13: =B13 -> Varios
A14: El Alamein | B14: Jon Latimer | C14: Propio | D14: 41217 | E14: 41319 | F14: 557 | G14: Historia | H14: 7 | I14: =NA() -> #N/A | J14: =B14 -> Jon Latimer
A15: Los buenos soldados | B15: David Finkel | C15: ebook | D15: 41265 | E15: 41282 | F15: 304 | G15: Historia | H15: 8 | I15: =NA() -> #N/A | J15: =B15 -> David Finkel
A16: Reamde | B16: Neal Stephenson | C16: ebook | D16: 41282 | E16: 41307 | F16: 992 | G16: Novela | H16: 8 | I16: =NA() -> #N/A | J16: =B16 -> Neal Stephenson
A17: El tercer reich | B17: Roberto Bolaño | C17: Propio | D17: 41320 | E17: 41333 | F17: 368 | G17: Novela | H17: 7 | I17: =NA() -> #N/A | J17: =B17 -> Roberto Bolaño
A18: Exitus | B18: Antonio Luque | C18: Propio | D18: 41334 | E18: 41360 | F18: 512 | G18: Novela | H18: 6.5 | I18: =NA() -> #N/A | J18: =B18 -> Antonio Luque
A19: El sueño de una noche de verano | B19: William Shakespeare | C19: ebook | D19: 41361 | E19: 41366 | F19: 144 | G19: Teatro | H19: 7 | I19: =NA() -> #N/A | J19: =B19 -> William Shakespeare
A20: El ávaro | B20: Moliere | C20: ebook | D20: 41366 | E20: 41368 | F20: 128 | G20: Teatro | H20: 7 | I20: =NA() -> #N/A | J20: =B20 -> Moliere
A21: Anabasis | B21: Jenofonte | C21: ebook | D21: 41368 | E21: 41379 | F21: 288 | G21: Historia | H21: 5 | I21: =NA() -> #N/A | J21: =B21 -> Jenofonte
A22: Atenas clásica | B22: Peter Funke | C22: ebook | D22: 41380 | E22: 41381 | F22: 142 | G22: Historia | H22: 8 | I22: =NA() -> #N/A | J22: =B22 -> Peter Funke
A23: La orestiada | B23: Esquilo | C23: ebook | D23: 41382 | E23: 41387 | F23: 200 | G23: Teatro | H23: 6 | I23: =NA() -> #N/A | J23: =B23 -> Esquilo
A24: Guerra Mundial Z | B24: Max Brooks | C24: ebook | D24: 41387 | E24: 41390 | F24: 480 | G24: Novela | H24: 8.6 | I24: =NA() -> #N/A | J24: =B24 -> Max Brooks
... A39: Honrarás a tu padre | B39: Gay Talese | C39: ebook | D39: 41519 | E39: 41620 | F39: 640 | G39: Ensayo | H39: 7 | I39: =NA() -> #N/A | J39: =B39 -> Gay Talese
F41: =SUM(F2:F39) -> 17259
A42: Estadísticas
A43: Libros Leídos | B43: Media páginas por libro | C43: Autor más leido | D43: Tipo más leido
A44: =COUNTIF(E2:E39,">0") -> 27 | B44: =ROUND(F41/A44,0) -> 639 | C44: =INDEX(J2:J39,MATCH(MAX(I2:I39),I2:I39,0),1) -> #N/A

Sheet Leídos 2014
A1: Titulo | B1: Autor | C1: Origen | D1: Fecha Inicio | E1: Fecha Fin | F1: Paginas | G1: Tipo | H1: Puntuación (del 1 al 10) | I1: Num leidos | J1: Autor | K1: Año
A2: Pedro Páramo;El llano en llamas | B2: Juan Rulfo | C2: Prestado | D2: 40150 | F2: 222 | G2: Novela | H2: - | I2: =NA() -> #N/A | J2: =B2 -> Juan Rulfo
A3: Ulises | B3: James Joyce | C3: Propio | D3: 40261 | F3: 910 | G3: Novela | H3: - | I3: =NA() -> #N/A | J3: =B3 -> James Joyce
A4: Diccionario del Diablo | B4: Ambrose Bierce | C4: ebook | D4: 40282 | F4: 480 | G4: Novela | H4: - | I4: =NA() -> #N/A | J4: =B4 -> Ambrose Bierce
A5: Johnny got his gun | B5: Dalton Trumbo | C5: ebook | D5: 40296 | F5: 209 | G5: Novela | H5: - | I5: =NA() -> #N/A | J5: =B5 -> Dalton Trumbo
A6: Nuestras hermanas las ratas | B6: Michel Dansel | C6: ebook | D6: 40366 | F6: 160 | G6: Ensayo | H6: - | I6: =NA() -> #N/A | J6: =B6 -> Michel Dansel
A7: Bolaño salvaje | B7: Varios | C7: Propio | D7: 40373 | F7: 502 | G7: Ensayo | H7: - | I7: =NA() -> #N/A | J7: =B7 -> Varios
A8: Historia de la Inquisición | B8: Primitivo Martínez | C8: ebook | D8: 40385 | F8: 384 | G8: Historia | H8: - | I8: =NA() -> #N/A | J8: =B8 -> Primitivo Martínez
A9: Nuestros orígenes | B9: Richard Leakey | C9: ebook | D9: 40438 | F9: 300 | G9: Antropología | H9: - | I9: =NA() -> #N/A | J9: =B9 -> Richard Leakey
A10: El libro de las ilusiones | B10: Paul Auster | C10: Propio | F10: 338 | G10: Novela | H10: - | I10: =NA() -> #N/A | J10: =B10 -> Paul Auster
A11: La búsqueda de la lengua perfecta | B11: Umberto Eco | C11: ebook | D11: 40655 | F11: 300 | G11: Ensayo | H11: - | I11: =NA() -> #N/A | J11: =B11 -> Umberto Eco
A12: La insurrección que viene | B12: Comité invisible | C12: Propio | D12: 40736 | F12: 144 | G12: Ensayo | H12: - | I12: =NA() -> #N/A | J12: =B12 -> Comité invisible
A13: Mongoliad | B13: Neal Stephenson | C13: Propio | D13: 41537 | E13: 41666 | F13: 473 | G13: Novela | H13: 7 | I13: =NA() -> #N/A | J13: =B13 -> Neal Stephenson
A14: Delicioso suicidio en grupo | B14: Arto Paasilinna | C14: ebook | D14: 41666 | E14: 41801 | F14: 280 | G14: Novela | H14: 6.5 | I14: =NA() -> #N/A | J14: =B14 -> Arto Paasilinna
A15: El año mil | B15: George Duby | C15: Propio | D15: 41722 | E15: 41737 | F15: 160 | G15: Historia | H15: 1 | I15: =NA() -> #N/A | J15: =B15 -> George Duby
A16: Un mapa en la cabeza | B16: Ken Jennings | C16: Propio | D16: 41737 | E16: 41761 | F16: 344 | G16: Ensayo | H16: 9 | I16: =NA() -> #N/A | J16: =B16 -> Ken Jennings
A17: Crónicas de la mafia | B17: Iñigo Domínguez | C17: Propio | D17: 41763 | E17: 41775 | F17: 431 | G17: Ensayo | H17: 9 | I17: =NA() -> #N/A | J17: =B17 -> Iñigo Domínguez
A18: Amanece que no es poco | B18: Jose Luis Cuerda | C18: Propio | D18: 41775 | E18: 41792 | F18: 312 | G18: Ensayo | H18: 9 | I18: =NA() -> #N/A | J18: =B18 -> Jose Luis Cuerda
A19: Los caminantes | B19: Carlos Sisi | C19: ebook | D19: 41801 | F19: 272 | G19: Novela | I19: =NA() -> #N/A | J19: =B19 -> Carlos Sisi
A20: La última batalla | B20: Eric Hobsbawm | C20: ebook | D20: 41827 | E20: 41871 | F20: 600 | G20: Historia | H20: 7 | I20: =NA() -> #N/A | J20: =B20 -> Eric Hobsbawm
A21: En las antípodas | B21: Bill Bryson | C21: ebook | D21: 41880 | E21: 41886 | F21: 432 | G21: Ensayo | H21: 8 | I21: =NA() -> #N/A | J21: =B21 -> Bill Bryson | K21: 1999
A22: Carlomagno | B22: Harold Lamb | C22: ebook | D22: 41886 | E22: 41899 | F22: 336 | G22: Historia | H22: 6.8 | I22: =NA() -> #N/A | J22: =B22 -> Harold Lamb | K22: 2002
A23: La guerra del Peloponeso | B23: Donald Kagan | C23: ebook | D23: 41899 | E23: 41984 | F23: 768 | G23: Historia | H23: 9 | I23: =NA() -> #N/A | J23: =B23 -> Donald Kagan | K23: 2003
A24: Fundación | B24: Isaac Asimov | C24: ebook | D24: 41984 | E24: 41993 | F24: 230 | G24: Novela | H24: 7 | I24: =NA() -> #N/A | J24: =B24 -> Isaac Asimov | K24: 1951
A25: Fundación e Imperio | B25: Isaac Asimov | C25: ebook | D25: 41993 | E25: 42015 | F25: 320 | G25: Novela | H25: 6.5 | I25: =NA() -> #N/A | J25: =B25 -> Isaac Asimov | K25: 1952
F26: =SUM(F2:F25) -> 8907 | I26: =NA() -> #N/A | J26: =NA() -> #N/A
A27: Estadísticas | I27: =NA() -> #N/A | J27: =NA() -> #N/A
A28: Libros Leídos | B28: Media páginas por libro | C28: Autor más leido | D28: Tipo más leido | I28: =NA() -> #N/A | J28: =NA() -> #N/A
A29: =COUNTIF(E2:E25,">0") -> 12 | B29: =ROUND(F26/A29,0) -> 742 | C29: =INDEX(J2:J53,MATCH(MAX(I2:I53),I2:I53,0),1) -> #N/A | I29: =NA() -> #N/A | J29: =NA() -> #N/A
I30: =NA() -> #N/A | J30: =NA() -> #N/A
I31: =NA() -> #N/A | J31: =NA() -> #N/A
I32: =NA() -> #N/A | J32: =NA() -> #N/A
I33: =NA() -> #N/A | J33: =NA() -> #N/A
I34: =NA() -> #N/A | J34: =NA() -> #N/A
I35: =NA() -> #N/A | J35: =NA() -> #N/A
I36: =NA() -> #N/A | J36: =NA() -> #N/A
I37: =NA() -> #N/A | J37: =NA() -> #N/A
I38: =NA() -> #N/A | J38: =NA() -> #N/A
I39: =NA() -> #N/A | J39: =NA() -> #N/A
I40: =NA() -> #N/A | J40: =NA() -> #N/A
...

Sheet Leídos 2015
A1: Titulo | B1: Autor | C1: Origen | D1: Fecha Inicio | E1: Fecha Fin | F1: Paginas | G1: Tipo | H1: Puntuación (del 1 al 10) | I1: Num leidos | J1: Autor | K1: Año
A2: Pedro Páramo;El llano en llamas | B2: Juan Rulfo | C2: Prestado | D2: 40150 | F2: 222 | G2: Novela | H2: - | I2: =NA() -> #N/A | J2: =B2 -> Juan Rulfo
A3: Ulises | B3: James Joyce | C3: Propio | D3: 40261 | F3: 910 | G3: Novela | H3: - | I3: =NA() -> #N/A | J3: =B3 -> James Joyce
A4: Diccionario del Diablo | B4: Ambrose Bierce | C4: ebook | D4: 40282 | F4: 480 | G4: Novela | H4: - | I4: =NA() -> #N/A | J4: =B4 -> Ambrose Bierce
A5: Johnny got his gun | B5: Dalton Trumbo | C5: ebook | D5: 40296 | F5: 209 | G5: Novela | H5: - | I5: =NA() -> #N/A | J5: =B5 -> Dalton Trumbo
A6: Nuestras hermanas las ratas | B6: Michel Dansel | C6: ebook | D6: 40366 | F6: 160 | G6: Ensayo | H6: - | I6: =NA() -> #N/A | J6: =B6 -> Michel Dansel
A7: Bolaño salvaje | B7: Varios | C7: Propio | D7: 40373 | F7: 502 | G7: Ensayo | H7: - | I7: =NA() -> #N/A | J7: =B7 -> Varios
A8: Historia de la Inquisición | B8: Primitivo Martínez | C8: ebook | D8: 40385 | F8: 384 | G8: Historia | H8: - | I8: =NA() -> #N/A | J8: =B8 -> Primitivo Martínez
A9: Nuestros orígenes | B9: Richard Leakey | C9: ebook | D9: 40438 | F9: 300 | G9: Antropología | H9: - | I9: =NA() -> #N/A | J9: =B9 -> Richard Leakey
A10: El libro de las ilusiones | B10: Paul Auster | C10: Propio | F10: 338 | G10: Novela | H10: - | I10: =NA() -> #N/A | J10: =B10 -> Paul Auster
A11: La búsqueda de la lengua perfecta | B11: Umberto Eco | C11: ebook | D11: 40655 | F11: 300 | G11: Ensayo | H11: - | I11: =NA() -> #N/A | J11: =B11 -> Umberto Eco
A12: La insurrección que viene | B12: Comité invisible | C12: Propio | D12: 40736 | F12: 144 | G12: Ensayo | H12: - | I12: =NA() -> #N/A | J12: =B12 -> Comité invisible
A13: Los caminantes | B13: Carlos Sisi | C13: ebook | D13: 41801 | F13: 272 | G13: Novela | H13: - | I13: =NA() -> #N/A | J13: =B13 -> Carlos Sisi
A14: Quemando cromo | B14: William Gibson | C14: ebook | D14: 42015 | F14: 232 | G14: Novela | H14: - | I14: =NA() -> #N/A | J14: =B14 -> William Gibson
A15: El marciano | B15: Andy Weir | C15: ebook | D15: 42027 | E15: 42040 | F15: 408 | G15: Novela | H15: 8 | J15: =B15 -> Andy Weir
A16: Verdes valles, colinas rojas 2: Los cuerpos desnudos | B16: Ramiro Pinilla | C16: ebook | D16: 42041 | E16: 42055 | F16: 776 | G16: Novela | H16: 9 | J16: =B16 -> Ramiro Pinilla
A17: Verdes valles, colinas rojas 3: Las cenizas del hierro | B17: Ramiro Pinilla | C17: ebook | D17: 42055 | E17: 42074 | F17: 656 | G17: Novela | H17: 9 | J17: =B17 -> Ramiro Pinilla
A18: La guerra civil española 1 | B18: Hugh Thomas | C18: ebook | D18: 42074 | E18: 42089 | F18: 600 | G18: Historia | H18: 7.5 | J18: =B18 -> Hugh Thomas
A19: La guerra civil española 2 | B19: Hugh Thomas | C19: ebook | D19: 42089 | E19: 42109 | F19: 600 | G19: Historia | H19: 7.5 | J19: =B19 -> Hugh Thomas
A20: El hombre anumérico | B20: John Paulos | C20: ebook | D20: 42109 | E20: 42117 | F20: 216 | G20: Divulgación | H20: 5 | J20: =B20 -> John Paulos
A21: La piel | B21: Curzio Malaparte | C21: ebook | D21: 42117 | E21: 42130 | F21: 400 | G21: Novela | H21: 7.6 | J21: =B21 -> Curzio Malaparte
A22: Crónicas del multiverso | B22: Victor Conde | C22: ebook | D22: 42130 | E22: 42142 | F22: 352 | G22: Novela | H22: 9 | J22: =B22 -> Victor Conde
A23: El disputado voto del señor Cayo | B23: Miguel Delibes | C23: ebook | D23: 42143 | E23: 42149 | F23: 192 | G23: Novela | H23: 7 | J23: =B23 -> Miguel Delibes
A24: Vientos de guerra | B24: Steven Pressfield | C24: ebook | D24: 42149 | E24: 42164 | F24: 528 | G24: Novela | H24: 8 | J24: =B24 -> Steven Pressfield
A25: La sombra del ciprés es alargada | B25: Miguel Delibes | C25: ebook | D25: 42164 | E25: 42173 | F25: 352 | G25: Novela | H25: 5 | J25: =B25 -> Miguel Delibes
A26: A las armas | B26: Quique Peinado | C26: Propio | D26: 42171 | E26: 42174 | F26: 109 | G26: Ensayo | H26: 9 | J26: =B26 -> Quique Peinado
... A34: Límite | B34: Frank Schazting | C34: ebook | D34: 42233 | E34: 42278 | F34: 1376 | G34: Novela | H34: 6 | J34: =B34 -> Frank Schazting
A35: Anatema | B35: Neal Stephenson | C35: Propio | D35: 42241 | F35: 736 | G35: Novela | I35: =NA() -> #N/A | J35: =B35 -> Neal Stephenson
A36: Pistola y cuchillo | B36: Montero González | C36: ebook | D36: 42279 | E36: 42283 | F36: 128 | G36: Novela | H36: 7.6 | I36: =NA() -> #N/A | J36: =B36 -> Montero González
A37: Dientes de gallina y dedos de caballo | B37: Stephen Jay Gould | C37: ebook | D37: 42283 | E37: 42297 | F37: 464 | G37: Divulgación | H37: 5 | I37: =NA() -> #N/A | J37: =B37 -> Stephen Jay Gould | K37: 1983
A38: Crematorio | B38: Rafael Chirbes | C38: ebook | D38: 42297 | E38: 42311 | F38: 424 | G38: Novela | H38: 8 | I38: =NA() -> #N/A | J38: =B38 -> Rafael Chirbes | K38: 2007
A39: La casa de Bernarda Alba | B39: Federico García Lorca | C39: ebook | D39: 42311 | E39: 42313 | F39: 288 | G39: Teatro | H39: 8 | I39: =NA() -> #N/A | J39: =B39 -> Federico García Lorca | K39: 1936
A40: Historia verdadera de la conquista de la Nueva España | B40: Bernar Diaz del Castillo | C40: ebook | D40: 42313 | F40: 1548 | G40: Historia | I40: =NA() -> #N/A | J40: =B40 -> Bernar Diaz del Castillo
A41: Tubos | B41: Andrew Blum | C41: ebook | D41: 42313 | E41: 42325 | F41: 272 | G41: Divulgación | H41: 6 | I41: =NA() -> #N/A | J41: =B41 -> Andrew Blum | K41: 2012
A42: La primera guerra mundial | B42: Martin Gilbert | C42: ebook | D42: 42325 | E42: 42354 | F42: 928 | G42: Historia | H42: 7 | I42: =NA() -> #N/A | J42: =B42 -> Martin Gilbert | K42: 2004
A43: Los santos inocentes | B43: Miguel Delibes | C43: ebook | D43: 42354 | E43: 42357 | F43: 192 | G43: Novela | H43: 8 | I43: =NA() -> #N/A | J43: =B43 -> Miguel Delibes | K43: 1981
F44: =SUMIFS(F2:F43,E2:E43,">0") -> 11891 | H44: =GEOMEAN(H2:H43) -> 7.2003484 | I44: =NA() -> #N/A | J44: =NA() -> #N/A
A45: Estadísticas | I45: =NA() -> #N/A | J45: =NA() -> #N/A
A46: Libros Leídos | B46: Media páginas por libro | C46: Autor más leido | D46: Tipo más leido | I46: =NA() -> #N/A | J46: =NA() -> #N/A
A47: =COUNTIF(E2:E43,">0") -> 27 | B47: =ROUND(F44/A47,0) -> 440 | C47: =INDEX(J2:J71,MATCH(MAX(I2:I71),I2:I71,0),1) -> #N/A | I47: =NA() -> #N/A | J47: =NA() -> #N/A
...

Sheet Leídos 2016
A1: Titulo | B1: Autor | C1: Origen | D1: Fecha Inicio | E1: Fecha Fin | F1: Paginas | G1: Tipo | H1: Puntuación (del 1 al 10) | I1: Num leidos | J1: Autor | K1: Año
A2: Pedro Páramo;El llano en llamas | B2: Juan Rulfo | C2: Prestado | D2: 40150 | F2: 222 | G2: Novela | H2: - | I2: =NA() -> #N/A | J2: =B2 -> Juan Rulfo
A3: Ulises | B3: James Joyce | C3: Propio | D3: 40261 | F3: 910 | G3: Novela | H3: - | I3: =NA() -> #N/A | J3: =B3 -> James Joyce
A4: Diccionario del Diablo | B4: Ambrose Bierce | C4: ebook | D4: 40282 | F4: 480 | G4: Novela | H4: - | I4: =NA() -> #N/A | J4: =B4 -> Ambrose Bierce
A5: Johnny got his gun | B5: Dalton Trumbo | C5: ebook | D5: 40296 | F5: 209 | G5: Novela | H5: - | I5: =NA() -> #N/A | J5: =B5 -> Dalton Trumbo
A6: Nuestras hermanas las ratas | B6: Michel Dansel | C6: ebook | D6: 40366 | F6: 160 | G6: Ensayo | H6: - | I6: =NA() -> #N/A | J6: =B6 -> Michel Dansel
A7: Bolaño salvaje | B7: Varios | C7: Propio | D7: 40373 | F7: 502 | G7: Ensayo | H7: - | I7: =NA() -> #N/A | J7: =B7 -> Varios
A8: Historia de la Inquisición | B8: Primitivo Martínez | C8: ebook | D8: 40385 | F8: 384 | G8: Historia | H8: - | I8: =NA() -> #N/A | J8: =B8 -> Primitivo Martínez
A9: Nuestros orígenes | B9: Richard Leakey | C9: ebook | D9: 40438 | F9: 300 | G9: Antropología | H9: - | I9: =NA() -> #N/A | J9: =B9 -> Richard Leakey
A10: El libro de las ilusiones | B10: Paul Auster | C10: Propio | F10: 338 | G10: Novela | H10: - | I10: =NA() -> #N/A | J10: =B10 -> Paul Auster
A11: La búsqueda de la lengua perfecta | B11: Umberto Eco | C11: ebook | D11: 40655 | F11: 300 | G11: Ensayo | H11: - | I11: =NA() -> #N/A | J11: =B11 -> Umberto Eco
A12: La insurrección que viene | B12: Comité invisible | C12: Propio | D12: 40736 | F12: 144 | G12: Ensayo | H12: - | I12: =NA() -> #N/A | J12: =B12 -> Comité invisible
A13: Los caminantes | B13: Carlos Sisi | C13: ebook | D13: 41801 | F13: 272 | G13: Novela | H13: - | I13: =NA() -> #N/A | J13: =B13 -> Carlos Sisi
A14: Quemando cromo | B14: William Gibson | C14: ebook | D14: 42015 | F14: 232 | G14: Novela | H14: - | I14: =NA() -> #N/A | J14: =B14 -> William Gibson
A15: Hindenburg | B15: Emil Ludwig | C15: ebook | D15: 42357 | E15: 42381 | F15: 560 | G15: Historia | H15: 6 | I15: =NA() -> #N/A | J15: =B15 -> Emil Ludwig | K15: 1935
A16: Rabia | B16: Stephen King | C16: ebook | D16: 42381 | E16: 42386 | F16: 277 | G16: Novela | H16: 7 | J16: =B16 -> Stephen King | K16: 1977
A17: ¿Porqué me comprastéis un walkie-talkie si era hijo único? | B17: Santi Balmes | C17: Propio | D17: 42387 | E17: 42396 | F17: 416 | G17: Novela | H17: 8 | J17: =B17 -> Santi Balmes | K17: 2015
A18: Polvo eres: peripecias y extravagancias de algunos cadaveres inqu ietos | B18: Nieves Concostrina | C18: ebook | D18: 42396 | E18: 42404 | F18: 396 | G18: Historia | H18: 7 | J18: =B18 -> Nieves Concostrina | K18: 2009
A19: La civilización romana | B19: Pierre Grimal | C19: ebook | D19: 42404 | E19: 42422 | F19: 336 | G19: Historia | H19: 7 | J19: =B19 -> Pierre Grimal | K19: 1960
A20: El imperio español: de Colón a Magallanes | B20: Hugh Thomas | C20: ebook | D20: 42422 | E20: 42441 | F20: 800 | G20: Historia | H20: 8 | J20: =B20 -> Hugh Thomas | K20: 2003
A21: HhhH | B21: Laurent Binet | C21: ebook | D21: 42441 | E21: 42451 | F21: 400 | G21: Novela | H21: 7.5 | J21: =B21 -> Laurent Binet | K21: 2011
A22: Fariña | B22: Nacho Carretero | C22: Propio | D22: 42452 | E22: 42459 | F22: 358 | G22: Ensayo | H22: 6.5 | J22: =B22 -> Nacho Carretero | K22: 2015
A23: El Bajo Imperio romano (284-430 d. de C.) | B23: Averil Cameron | C23: ebook | D23: 42457 | E23: 42467 | F23: 240 | G23: Historia | H23: 8.5 | J23: =B23 -> Averil Cameron | K23: 2002
A24: Manual del Perfecto Festivalero | B24: Manuel Bartual | C24: Propio | D24: 42467 | E24: 42473 | F24: 360 | G24: Música | H24: 9 | J24: =B24 -> Manuel Bartual | K24: 2015
A25: Ojo en el cielo | B25: Philip K.Dick | C25: ebook | D25: 42474 | E25: 42481 | F25: 292 | G25: Novela | H25: 6.5 | J25: =B25 -> Philip K.Dick | K25: 1957
A26: 091: aullidos, corazones y guitarras | B26: Juan Jesús García | C26: Propio | D26: 42481 | E26: 42488 | F26: 192 | G26: Música | H26: 8.75 | J26: =B26 -> Juan Jesús García | K26: 2016
A27: Monsieur Pain | B27: Roberto Bolaño | C27: ebook | D27: 42488 | E27: 42496 | F27: 176 | G27: Novela | H27: 7 | J27: =B27 -> Roberto Bolaño | K27: 1999
... A39: La cruzada del sur | B39: Juan Antonio Cebrian | C39: ebook | D39: 42595 | E39: 42601 | F39: 256 | G39: Historia | H39: 5 | J39: =B39 -> Juan Antonio Cebrian | K39: 2003
A40: Mystes | B40: Victor Conde | C40: ebook | D40: 42601 | E40: 42602 | F40: 224 | G40: Novela | H40: 6 | K40: 2004
A41: Plenilunio | B41: Antonio Muñoz Molina | C41: ebook | D41: 42602 | E41: 42616 | F41: 384 | G41: Novela | H41: 7 | K41: 1997
A42: Seveneves | B42: Neal Stephenson | C42: ebook | D42: 42616 | E42: 42626 | F42: 816 | G42: Novela | H42: 9 | K42: 2016
A43: Temerario I. El dragón de su majestad | B43: Naomi Novik | C43: ebook | D43: 42626 | E43: 42632 | F43: 416 | G43: Novela | H43: 7 | K43: 2006
A44: El ojo del mundo | B44: Robert Jordan | C44: ebook | D44: 42632 | E44: 42653 | F44: 640 | G44: Novela | H44: 8.5 | K44: 1990
A45: SPQR | B45: Mary Beard | C45: ebook | D45: 42653 | E45: 42669 | F45: 664 | G45: Historia | H45: 8.9 | K45: 2016
A46: Roma eterna | B46: Robert Silverberg | C46: ebook | D46: 42669 | E46: 42682 | F46: 400 | G46: Novela | H46: 7 | K46: 2003
A47: 1927: un verano que cambió el mundo | B47: Bill Bryson | C47: ebook | D47: 42682 | E47: 42693 | F47: 624 | G47: Divulgación | H47: 8 | K47: 2015
A48: El despertar de los héroes | B48: Robert Jordan | C48: ebook | D48: 42694 | E48: 42718 | F48: 558 | G48: Novela | H48: 8 | K48: 1991
A49: Cosas que los nietos deberían saber | B49: Mark Oliver Everett | C49: ebook | D49: 42718 | E49: 42721 | F49: 224 | G49: Biografía | H49: 7.9 | K49: 2009
F50: =SUMIFS(F2:F45,E2:E45,">0") -> 13222 | H50: =GEOMEAN(H2:H45) -> 7.1305769 | I50: =NA() -> #N/A | J50: =NA() -> #N/A
A51: Estadísticas | I51: =NA() -> #N/A | J51: =NA() -> #N/A
...

Sheet Leídos 2017
A1: Titulo | B1: Autor | C1: Origen | D1: Fecha Inicio | E1: Fecha Fin | F1: Paginas | G1: Tipo | H1: Puntuación (del 1 al 10) | I1: Num leidos | J1: Autor | K1: Año
A2: Pedro Páramo;El llano en llamas | B2: Juan Rulfo | C2: Prestado | D2: 40150 | F2: 222 | G2: Novela | H2: - | I2: =NA() -> #N/A | J2: =B2 -> Juan Rulfo
A3: Ulises | B3: James Joyce | C3: Propio | D3: 40261 | F3: 910 | G3: Novela | H3: - | I3: =NA() -> #N/A | J3: =B3 -> James Joyce
A4: Diccionario del Diablo | B4: Ambrose Bierce | C4: ebook | D4: 40282 | F4: 480 | G4: Novela | H4: - | I4: =NA() -> #N/A | J4: =B4 -> Ambrose Bierce
A5: Johnny got his gun | B5: Dalton Trumbo | C5: ebook | D5: 40296 | F5: 209 | G5: Novela | H5: - | I5: =NA() -> #N/A | J5: =B5 -> Dalton Trumbo
A6: Nuestras hermanas las ratas | B6: Michel Dansel | C6: ebook | D6: 40366 | F6: 160 | G6: Ensayo | H6: - | I6: =NA() -> #N/A | J6: =B6 -> Michel Dansel
A7: Bolaño salvaje | B7: Varios | C7: Propio | D7: 40373 | F7: 502 | G7: Ensayo | H7: - | I7: =NA() -> #N/A | J7: =B7 -> Varios
A8: Historia de la Inquisición | B8: Primitivo Martínez | C8: ebook | D8: 40385 | F8: 384 | G8: Historia | H8: - | I8: =NA() -> #N/A | J8: =B8 -> Primitivo Martínez
A9: Nuestros orígenes | B9: Richard Leakey | C9: ebook | D9: 40438 | F9: 300 | G9: Antropología | H9: - | I9: =NA() -> #N/A | J9: =B9 -> Richard Leakey
A10: El libro de las ilusiones | B10: Paul Auster | C10: Propio | F10: 338 | G10: Novela | H10: - | I10: =NA() -> #N/A | J10: =B10 -> Paul Auster
A11: La búsqueda de la lengua perfecta | B11: Umberto Eco | C11: ebook | D11: 40655 | F11: 300 | G11: Ensayo | H11: - | I11: =NA() -> #N/A | J11: =B11 -> Umberto Eco
A12: La insurrección que viene | B12: Comité invisible | C12: Propio | D12: 40736 | F12: 144 | G12: Ensayo | H12: - | I12: =NA() -> #N/A | J12: =B12 -> Comité invisible
A13: Los caminantes | B13: Carlos Sisi | C13: ebook | D13: 41801 | F13: 272 | G13: Novela | H13: - | I13: =NA() -> #N/A | J13: =B13 -> Carlos Sisi
A14: Quemando cromo | B14: William Gibson | C14: ebook | D14: 42015 | F14: 232 | G14: Novela | H14: - | I14: =NA() -> #N/A | J14: =B14 -> William Gibson
A15: 1914: de la paz a la guerra | B15: Margaret Macmillan | C15: ebook | D15: 42722 | E15: 42746 | F15: 864 | G15: Historia | H15: 8 | K15: 2016
A16: Nocturno de Chile | B16: Roberto Bolaño | C16: ebook | D16: 42746 | E16: 42748 | F16: 152 | G16: Novela | H16: 8 | I16: =NA() -> #N/A | J16: =B16 -> Roberto Bolaño | K16: 2000
A17: Metro 2033 | B17: Dmitri Glujovski | C17: ebook | D17: 42748 | E17: 42768 | F17: 544 | G17: Novela | H17: 6 | I17: =NA() -> #N/A | J17: =B17 -> Dmitri Glujovski | K17: 2007
A18: Ojos de fuego | B18: Stephen King | C18: ebook | D18: 42768 | E18: 42783 | F18: 592 | G18: Novela | H18: 6 | I18: =NA() -> #N/A | J18: =B18 -> Stephen King | K18: 1980
A19: Tres días y una vida | B19: Pierre Lemaitre | C19: ebook | D19: 42784 | E19: 42795 | F19: 224 | G19: Novela | H19: 7 | I19: =NA() -> #N/A | J19: =B19 -> Pierre Lemaitre | K19: 2016
A20: Sapiens, de animales a dioses | B20: Yuval Noah Harari | C20: ebook | D20: 42796 | E20: 42807 | F20: 496 | G20: Ensayo | H20: 8 | I20: =NA() -> #N/A | J20: =B20 -> Yuval Noah Harari | K20: 2014
A21: Armagedon: la derrota de Alemania | B21: Max Hastings | C21: ebook | D21: 42807 | E21: 42842 | F21: 856 | G21: Historia | H21: 7 | I21: =NA() -> #N/A | J21: =B21 -> Max Hastings | K21: 2005
A22: El dragón renacido | B22: Robert Jordan | C22: ebook | D22: 42842 | E22: 42864 | F22: 512 | G22: Novela | H22: 7.5 | I22: =NA() -> #N/A | J22: =B22 -> Robert Jordan | K22: 1991
A23: El aumento de la sombra | B23: Robert Jordan | C23: ebook | D23: 42864 | E23: 42886 | F23: 1013 | G23: Novela | H23: 7.6 | I23: =NA() -> #N/A | J23: =B23 -> Robert Jordan | K23: 1992
A24: Las lagartijas no se hacen preguntas | B24: Leonard Mlodinow | C24: ebook | D24: 42886 | E24: 42891 | F24: 416 | G24: Divulgación | H24: 9 | I24: =NA() -> #N/A | J24: =B24 -> Leonard Mlodinow | K24: 2016
A25: Huevo del dragón (cheela 1) | B25: Robert L. Forward | C25: ebook | D25: 42891 | E25: 42899 | F25: 330 | G25: Novela | H25: 6 | I25: =NA() -> #N/A | J25: =B25 -> Robert L. Forward | K25: 1980
A26: Don Quijote de la Mancha | B26: Miguel de Cervantes Saavedra | C26: ebook | D26: 42897 | F26: 573 | G26: Novela | I26: =NA() -> #N/A | J26: =B26 -> Miguel de Cervantes Saavedra | K26: 1605
A27: El atlas de las nubes | B27: David Mitchell | C27: ebook | D27: 42899 | E27: 42909 | F27: 608 | G27: Novela | H27: 8 | I27: =NA() -> #N/A | J27: =B27 -> David Mitchell | K27: 2004
A28: El sueño de Galileo | B28: Kim Stanley Robinson | C28: ebook | D28: 42910 | E28: 42919 | F28: 544 | G28: Novela | H28: 6 | I28: =NA() -> #N/A | J28: =B28 -> Kim Stanley Robinson | K28: 2010
A29: Moby Dick | B29: Herman Melville | C29: ebook | D29: 42920 | E29: 42943 | F29: 544 | G29: Novela | H29: 6 | I29: =NA() -> #N/A | J29: =B29 -> Herman Melville | K29: 1860
A30: El cielo en llamas | B30: Robert Jordan | C30: ebook | D30: 42943 | E30: 42970 | F30: 512 | G30: Novela | H30: 6.5 | I30: =NA() -> #N/A | J30: =B30 -> Robert Jordan | K30: 1993
A31: La torre oscura 1: el pistolero | B31: Stephen King | C31: ebook | D31: 42970 | E31: 42974 | F31: 236 | G31: Novela | H31: 6 | I31: =NA() -> #N/A | J31: =B31 -> Stephen King | K31: 1982
A32: 2312 | B32: Kim Stanley Robinson | C32: ebook | D32: 42974 | E32: 42985 | F32: 528 | G32: Novela | H32: 4.5 | I32: =NA() -> #N/A | J32: =B32 -> Kim Stanley Robinson | K32: 2012
A33: Ritos iguales | B33: Terry Pratchett | C33: ebook | D33: 42987 | E33: 42993 | F33: 272 | G33: Novela | H33: 8 | I33: =NA() -> #N/A | J33: =B33 -> Terry Pratchett | K33: 1987
A34: Homo deus | B34: Yuval Noah Harari | C34: ebook | D34: 42993 | E34: 43007 | F34: 496 | G34: Ensayo | H34: 8.5 | I34: =NA() -> #N/A | J34: =B34 -> Yuval Noah Harari | K34: 2015
A35: Brujerías | B35: Terry Pratchett | C35: ebook | D35: 43007 | E35: 43019 | F35: 328 | G35: Novela | H35: 8.5 | I35: =NA() -> #N/A | J35: =B35 -> Terry Pratchett | K35: 1992
A36: La guerra secreta 1939-1945 | B36: Max Hastings | C36: ebook | D36: 43019 | E36: 43046 | F36: 824 | G36: Ensayo | H36: 7.5 | I36: =NA() -> #N/A | J36: =B36 -> Max Hastings | K36: 2016
A37: Miles Vorkosigan IV - El aprendiz del guerrero | B37: Lois McMaster Bujold | C37: ebook | D37: 43046 | E37: 43062 | F37: 432 | G37: Novela | H37: 7.9 | I37: =NA() -> #N/A | J37: =B37 -> Lois McMaster Bujold | K37: 1986
A38: Miles Vorkosigan V - Fronteras del infinito | B38: Lois McMaster Bujold | C38: ebook | D38: 43062 | E38: 43067 | F38: 384 | G38: Novela | H38: 8.5 | I38: =NA() -> #N/A | J38: =B38 -> Lois McMaster Bujold | K38: 1989
A39: Miles Vorkosigan VI - El juego de los Vor | B39: Lois McMaster Bujold | C39: ebook | D39: 43067 | E39: 43076 | F39: 448 | G39: Novela | H39: 8 | I39: =NA() -> #N/A | J39: =B39 -> Lois McMaster Bujold | K39: 1990
A40: Chavs: la demonización de la clase obrera | B40: Owen Jones | C40: ebook | D40: 43076 | E40: 43086 | F40: 360 | G40: Ensayo | H40: 4 | I40: =NA() -> #N/A | J40: =B40 -> Owen Jones | K40: 2011
...

Sheet Leídos 2018
A1: Titulo | B1: Autor | C1: Origen | D1: Fecha Inicio | E1: Fecha Fin | F1: Paginas | G1: Tipo | H1: Puntuación (del 1 al 10) | I1: Num leidos | J1: Autor | K1: Año
A2: Pedro Páramo;El llano en llamas | B2: Juan Rulfo | C2: Prestado | D2: 40150 | F2: 222 | G2: Novela | H2: - | I2: =NA() -> #N/A | J2: =B2 -> Juan Rulfo
A3: Ulises | B3: James Joyce | C3: Propio | D3: 40261 | F3: 910 | G3: Novela | H3: - | I3: =NA() -> #N/A | J3: =B3 -> James Joyce
A4: Diccionario del Diablo | B4: Ambrose Bierce | C4: ebook | D4: 40282 | F4: 480 | G4: Novela | H4: - | I4: =NA() -> #N/A | J4: =B4 -> Ambrose Bierce
A5: Johnny got his gun | B5: Dalton Trumbo | C5: ebook | D5: 40296 | F5: 209 | G5: Novela | H5: - | I5: =NA() -> #N/A | J5: =B5 -> Dalton Trumbo
A6: Nuestras hermanas las ratas | B6: Michel Dansel | C6: ebook | D6: 40366 | F6: 160 | G6: Ensayo | H6: - | I6: =NA() -> #N/A | J6: =B6 -> Michel Dansel
A7: Bolaño salvaje | B7: Varios | C7: Propio | D7: 40373 | F7: 502 | G7: Ensayo | H7: - | I7: =NA() -> #N/A | J7: =B7 -> Varios
A8: Historia de la Inquisición | B8: Primitivo Martínez | C8: ebook | D8: 40385 | F8: 384 | G8: Historia | H8: - | I8: =NA() -> #N/A | J8: =B8 -> Primitivo Martínez
A9: Nuestros orígenes | B9: Richard Leakey | C9: ebook | D9: 40438 | F9: 300 | G9: Antropología | H9: - | I9: =NA() -> #N/A | J9: =B9 -> Richard Leakey
A10: El libro de las ilusiones | B10: Paul Auster | C10: Propio | F10: 338 | G10: Novela | H10: - | I10: =NA() -> #N/A | J10: =B10 -> Paul Auster
A11: La búsqueda de la lengua perfecta | B11: Umberto Eco | C11: ebook | D11: 40655 | F11: 300 | G11: Ensayo | H11: - | I11: =NA() -> #N/A | J11: =B11 -> Umberto Eco
A12: La insurrección que viene | B12: Comité invisible | C12: Propio | D12: 40736 | F12: 144 | G12: Ensayo | H12: - | I12: =NA() -> #N/A | J12: =B12 -> Comité invisible
A13: Los caminantes | B13: Carlos Sisi | C13: ebook | D13: 41801 | F13: 272 | G13: Novela | H13: - | I13: =NA() -> #N/A | J13: =B13 -> Carlos Sisi
A14: Quemando cromo | B14: William Gibson | C14: ebook | D14: 42015 | F14: 232 | G14: Novela | H14: - | I14: =NA() -> #N/A | J14: =B14 -> William Gibson
A15: Don Quijote de la Mancha | B15: Miguel de Cervantes Saavedra | C15: ebook | D15: 42897 | E15: 43200 | F15: 573 | G15: Novela | H15: 8 | I15: =NA() -> #N/A | J15: =B15 -> Miguel de Cervantes Saavedra | K15: 1605
A16: ¡Guardias! ¿Guardias? | B16: Terry Pratchett | C16: ebook | D16: 43100 | E16: 43119 | F16: 400 | G16: Novela | H16: 8 | K16: 1993
A17: Historia inventada del punk | B17: Juarma / Jorge B. Ortiz | C17: Propio | D17: 43105 | E17: 43105 | F17: 40 | G17: Comic | H17: 8 | K17: 2017
A18: Cuatro millones de golpes | B18: Erik Jimenez | C18: Propio | D18: 43105 | E18: 43114 | F18: 288 | G18: Biografía | H18: 7 | K18: 2017
A19: Prohibido Nacer | B19: Trevor Noah | C19: Propio | D19: 43115 | E19: 43242 | F19: 328 | G19: Biografía | H19: 6 | K19: 2017
A20: Hombres de armas | B20: Terry Pratchett | C20: ebook | D20: 43119 | E20: 43142 | F20: 352 | G20: Novela | H20: 8 | K20: 1993
A21: Pies de barro | B21: Terry Pratchett | C21: ebook | D21: 43143 | E21: 43159 | F21: 368 | G21: Novela | H21: 8.5 | K21: 1996
A22: !Voto a bríos! | B22: Terry Pratchett | C22: ebook | D22: 43160 | E22: 43169 | F22: 400 | G22: Novela | H22: 9 | K22: 1997
A23: La amiga estupenda | B23: Elena Ferrante | C23: ebook | D23: 43169 | E23: 43182 | F23: 392 | G23: Novela | H23: 8 | K23: 2011
A24: (Ekumen 2) Planeta de exilio | B24: Ursula K. Le Guin | C24: ebook | D24: 43200 | E24: 43206 | F24: 224 | G24: Novela | H24: 7.8 | K24: 1966
A25: Aurora | B25: Kim Stanley Robinson | C25: ebook | D25: 43206 | E25: 43224 | F25: 448 | G25: Novela | H25: 7 | K25: 2015
A26: Manual de Historia medieval | B26: Jose Angel Sesma Muñoz y Jose Angel García de Cortazar | C26: ebook | D26: 43224 | E26: 43258 | F26: 584 | G26: Historia | H26: 7.5 | K26: 2015
A27: La historia del Heavy Metal | B27: Andrew O´Neil | C27: Propio | D27: 43229 | E27: 43233 | F27: 352 | G27: Historia | H27: 9 | K27: 2018
... A31: La gente de la edad media | B31: Robert Fossier | C31: ebook | D31: 43280 | E31: 43296 | F31: 392 | G31: Historia | H31: 7 | K31: 2007
A32: Miles Vorkosigan VIII - Ethan de Athos | B32: Lois McMaster Bujold | C32: ebook | D32: 43297 | E32: 43299 | F32: 224 | G32: Novela | H32: 7.5 | I32: =NA() -> #N/A | J32: =B32 -> Lois McMaster Bujold | K32: 1986
A33: Miles Vorkosigan IX - Hermanos de armas | B33: Lois McMaster Bujold | C33: ebook | D33: 43299 | E33: 43301 | F33: 400 | G33: Novela | H33: 7.3 | K33: 1989
A34: Cinco ecuaciones que cambiaron el mundo | B34: Michael Guillen | C34: ebook | D34: 43302 | E34: 43303 | F34: 288 | G34: Ensayo | H34: 7 | K34: 1995
A35: Ciudad Permutación | B35: Greg Egan | C35: ebook | D35: 43303 | E35: 43316 | F35: 416 | G35: Novela | H35: 6 | K35: 1994
A36: (Ekumen 3) La ciudad de las ilusiones | B36: Ursula K. Le Guin | C36: ebook | D36: 43297 | E36: 43318 | F36: 256 | G36: Novela | H36: 8 | K36: 1967
A37: La partícula divina | B37: Leon Max Lederman | C37: ebook | D37: 43309 | E37: 43329 | F37: 616 | G37: Ensayo | H37: 8 | K37: 1993
A38: Nemesis: la derrota de Japón 1944-1945 | B38: Max Hastings | C38: ebook | D38: 43329 | E38: 43361 | F38: 880 | G38: Historia | H38: 9 | K38: 2008
A39: El estado de las cosas | B39: Roberto Herreros / Isidro Lopez | C39: Propio | D39: 43354 | E39: 43371 | F39: 226 | G39: Música | H39: 7 | K39: 2018
A40: El bosque oscuro | B40: Liu Cixin | C40: ebook | D40: 43362 | E40: 43401 | F40: 600 | G40: Novela | H40: 8 | K40: 2008
A41: El misterio de la orquídea calavera | B41: Elmer Mendoza | C41: ebook | D41: 43401 | E41: 43412 | F41: 296 | G41: Novela | H41: 9 | K41: 2014
A42: Nacidos de la bruma 1: El imperio final | B42: Brandon Sanderson | C42: ebook | D42: 43412 | E42: 43435 | F42: 688 | G42: Novela | H42: 9 | K42: 2006
A43: Nacidos de la bruma 2: El pozo de la ascensión | B43: Brandon Sanderson | C43: ebook | D43: 43435 | E43: 43465 | F43: 800 | G43: Novela | H43: 9 | K43: 2007
...

Sheet Leídos 2019
A1: Titulo | B1: Autor | C1: Origen | D1: Fecha Inicio | E1: Fecha Fin | F1: Paginas | G1: Tipo | H1: Puntuación (del 1 al 10) | I1: Num leidos | J1: Autor | K1: Año
A2: (Ekumen 4) La mano izquierda de la oscuridad | B2: Ursula K. Le Guin | C2: ebook | D2: 43318 | F2: 304 | G2: Novela | K2: 1969
A3: La sustancia del mal | B3: Luca D. Andrea | C3: Prestado | D3: 43372 | F3: 472 | G3: Novela | K3: 2016
A4: El fin de la muerte | B4: Liu Cixin | C4: ebook | D4: 43466 | E4: 43490 | F4: 736 | G4: Novela | H4: 8 | K4: 2008
A5: Un ascensor al espacio | B5: Kelly y Zach Weinersmith | C5: Propio | D5: 43469 | E5: 43585 | F5: 480 | G5: Ciencia | H5: 8 | K5: 2018
A6: El señor del caos | B6: Robert Jordan | C6: ebook | D6: 43490 | E6: 43574 | F6: 560 | G6: Novela | H6: 8 | K6: 1994
A7: Poema del mio Cid | B7: Anonimo | C7: Prestado | D7: 43497 | E7: 43532 | F7: 336 | G7: Poema | H7: 8 | K7: 1152
A8: Ciudad Abismo | B8: Alastair Reynolds | C8: ebook | D8: 43575 | E8: 43609 | F8: 512 | G8: Novela | H8: 9 | K8: 2001
A9: Nacer Crecer Metallica Morir Tomo 1 | B9: Paul Brannigan | C9: Propio | D9: 43590 | E9: 43600 | F9: 400 | G9: Música | H9: 8 | K9: 2018
A10: Los desnudos y los muertos | B10: Norman Mailer | C10: Propio | D10: 43601 | E10: 43737 | F10: 721 | G10: Novela | H10: 8 | K10: 1948
A11: Buenos presagios | B11: Neil Gaiman y Terry Pratchett | C11: ebook | D11: 43609 | E11: 43623 | F11: 352 | G11: Novela | H11: 8.7 | K11: 1990
A12: El prefecto | B12: Alastair Reynolds | C12: ebook | D12: 43623 | E12: 43637 | F12: 416 | G12: Novela | H12: 8.5 | K12: 2007
A13: El arca de la redención | B13: Alastair Reynolds | C13: ebook | D13: 43637 | E13: 43666 | F13: 608 | G13: Novela | H13: 8 | K13: 2002
A14: La quinta estación | B14: N. K. Jemisin | C14: ebook | D14: 43666 | E14: 43694 | F14: 448 | G14: Novela | H14: 8 | K14: 2015
A15: Marvel Classic La odisea | B15: Roy Thomas, Greg Tocchini | C15: Propio | D15: 43673 | E15: 43673 | F15: 200 | G15: Comic | H15: 8 | K15: 2013
... A22: Miles Vorkosigan X - Danza de espejos | B22: Lois McMaster Bujold | C22: ebook | D22: 43784 | E22: 43800 | F22: 507 | G22: Novela | H22: 8 | K22: 1995
A23: La extraordinaria familia Telemacus | B23: Daryl Gregory | C23: Propio | D23: 43790 | F23: 416 | G23: Novela | K23: 2017
A24: Miles Vorkosigan XI - Recuerdos | B24: Lois McMaster Bujold | C24: ebook | D24: 43800 | E24: 43806 | F24: 608 | G24: Novela | H24: 8 | K24: 1997
A25: Miles Vorkosigan XII - Komarr | B25: Lois McMaster Bujold | C25: ebook | D25: 43806 | E25: 43814 | F25: 352 | G25: Novela | H25: 8 | K25: 1998
A26: El desfiladero de la absolución | B26: Alastair Reynolds | C26: ebook | D26: 43814 | E26: 43830 | F26: 640 | G26: Novela | H26: 7 | K26: 2003
F27: =SUMIFS(F2:F26,E2:E26,">0") -> 10870 | H27: =GEOMEAN(H4:H26) -> 8.0060097 | I27: =NA() -> #N/A | J27: =NA() -> #N/A
A28: Estadísticas | I28: =NA() -> #N/A | J28: =NA() -> #N/A
A29: Libros Leídos | B29: Media páginas por libro | C29: Autor más leido | D29: Tipo más leido | I29: =NA() -> #N/A | J29: =NA() -> #N/A
A30: =COUNTIF(E2:E26,">0") -> 22 | B30: =ROUND(F27/A30,0) -> 494 | C30: =INDEX(J4:J54,MATCH(MAX(I4:I54),I4:I54,0),1) -> #N/A | I30: =NA() -> #N/A | J30: =NA() -> #N/A
I31: =NA() -> #N/A | J31: =NA() -> #N/A
I32: =NA() -> #N/A | J32: =NA() -> #N/A
I33: =NA() -> #N/A | J33: =NA() -> #N/A
A34: Un ejercito al amanecer | B34: Rick Atkinson | C34: ebook | D34: 40702 | E34: 40721 | F34: 672 | G34: Historia | H34: 6.5 | I34: =NA() -> #N/A | J34: =B34 -> Rick Atkinson
I35: =NA() -> #N/A | J35: =NA() -> #N/A
I36: =NA() -> #N/A | J36: =NA() -> #N/A
I37: =NA() -> #N/A | J37: =NA() -> #N/A
I38: =NA() -> #N/A | J38: =NA() -> #N/A
I39: =NA() -> #N/A | J39: =NA() -> #N/A
I40: =NA() -> #N/A | J40: =NA() -> #N/A
I41: =NA() -> #N/A | J41: =NA() -> #N/A
I42: =NA() -> #N/A | J42: =NA() -> #N/A
I43: =NA() -> #N/A | J43: =NA() -> #N/A
I44: =NA() -> #N/A | J44: =NA() -> #N/A
I45: =NA() -> #N/A | J45: =NA() -> #N/A
I46: =NA() -> #N/A | J46: =NA() -> #N/A
...

Sheet Leídos 2020
A1: Titulo | B1: Autor | C1: Origen | D1: Fecha Inicio | E1: Fecha Fin | F1: Paginas | G1: Tipo | H1: Puntuación (del 1 al 10) | I1: Num leidos | J1: Autor | K1: Año
A2: (Ekumen 4) La mano izquierda de la oscuridad | B2: Ursula K. Le Guin | C2: ebook | D2: 43318 | F2: 304 | G2: Novela | K2: 1969
A3: La sustancia del mal | B3: Luca D. Andrea | C3: Prestado | D3: 43372 | E3: 43997 | F3: 472 | G3: Novela | H3: 0 | K3: 2016
A4: La extraordinaria familia Telemacus | B4: Daryl Gregory | C4: Propio | D4: 43790 | E4: 44150 | F4: 416 | G4: Novela | H4: 0 | K4: 2017
A5: Los jardines de la Luna (Malaz: El Libro de los Caídos 1) | B5: Steven Erikson | C5: ebook | D5: 43830 | E5: 43860 | F5: 768 | G5: Novela | H5: 8 | K5: 1999
A6: Las puertas de la Casa de la Muerte (Malaz: El Libro de los Caídos 2) | B6: Steven Erikson | C6: ebook | D6: 43860 | E6: 43889 | F6: 943 | G6: Novela | H6: 8 | K6: 2000
A7: Hijos de una guerra: Los Hermanos Quero y la resistencia antifranquista | B7: Jorge Marco Carretero | C7: Propio | D7: 43870 | E7: 43884 | F7: 448 | G7: Historia | H7: 9 | K7: 2019
A8: Memorias del Hielo (Malaz: El Libro de los Caídos 3) | B8: Steven Erikson | C8: ebook | D8: 43889 | E8: 44185 | F8: 1184 | G8: Novela | H8: 7 | K8: 2001
A9: 14 de Julio | B9: Eric Villard | C9: ebook | D9: 43908 | E9: 43916 | F9: 192 | G9: Historia | H9: 3 | K9: 2016
A10: Fariña, la novela gráfica | B10: Luis Bustos | C10: Propio | D10: 43909 | E10: 43912 | F10: 128 | G10: Historieta | H10: 8.5 | K10: 2020
A11: Diario del año de la peste | B11: Daniel Defoe | C11: ebook | D11: 43916 | E11: 43936 | F11: 328 | G11: Historia | H11: 7 | K11: 1722
A12: El lector de Julio Verne | B12: Almudena Grandes | C12: Propio | D12: 43929 | E12: 44113 | F12: 417 | G12: Novela | H12: 7.5 | K12: 2020
A13: Miles Vorkosigan XIII – Una campaña civil | B13: Lois McMaster Bujold | C13: ebook | D13: 43936 | E13: 43968 | F13: 496 | G13: Novela | H13: 8 | K13: 1999
A14: Las legendarias aventuras de Chiquito | B14: Sergio Mora | C14: Propio | D14: 43830 | E14: 43958 | F14: 192 | G14: Historieta | H14: 10 | K14: 2019
... A16: Casa de soles | B16: Alastair Reynolds | C16: ebook | D16: 43970 | E16: 43996 | F16: 384 | G16: Cuento | H16: 7 | K16: 2004
A17: Historia verdadera de la conquista de la Nueva España | B17: Bernal Diaz del Castillo | C17: ebook | D17: 43976 | F17: 1051 | G17: Historia | K17: 1632
A18: La Italia del año mil | B18: Indro Montanelli | C18: Prestado | D18: 43987 | E18: 43995 | F18: 302 | G18: Historia | H18: 8 | K18: 1966
A19: Cuentos de Canterbury | B19: Geoffrey Chaucer | C19: ebook | D19: 43996 | E19: 44070 | F19: 646 | G19: Cuentos | H19: 7 | K19: 1392
A20: Flores para Algernon | B20: Daniel Keyes | C20: ebook | D20: 44009 | E20: 44016 | F20: 311 | G20: Novela | H20: 8 | K20: 1959
A21: Cortés | B21: Christian Duverger | C21: ebook | D21: 44016 | E21: 44017 | F21: 480 | G21: Historia | H21: 7 | K21: 2013
A22: Asinaria - Aulularia - Miles Gloriosus | B22: Tito Maccio Plauto | C22: ebook | D22: 44017 | E22: 44020 | F22: 153 | G22: Teatro | H22: 7 | K22: -206
A23: Super Freakonomics | B23: Stephen Levitt y Stephen Dubner | C23: ebook | D23: 44022 | E23: 44024 | F23: 320 | G23: Divulgación | H23: 9 | K23: 2010
